try {
  // Produce a Reference Error
  myFunction();
} catch(e) {
  console.log(e);
}

console.log('Program continues....');